File: gmFile/testfile/Bi2201Gd(041029)nonannealed050623_B_scan.dc.dat
[Header]
TITLE,MPMS DC Measurement
BYAPP,MPMS Measurement,2.0,Summary
FILEOPENTIME, 1119503968.060000 6/23/2005, 2:19:28 PM

INFO, APPNAME, MPMS MultiVu Application, Revision 1.52,  Build 049

INFO, NAME, Bi2201Gd(041029)nonannealed
INFO, WEIGHT, 28.900
INFO, AREA, 1.000
INFO, LENGTH, 0.500
INFO, SHAPE, 0
INFO, COMMENT,
INFO, SEQUENCE FILE: Bi2201Gd_B_scan(050623byHarada).seq


INFO, BACKGROUND DATA FILE:, None


STARTUPAXIS,X,4,LINEAR,AUTO,0.000000,0.000000
STARTUPAXIS,Y1,5,LINEAR,AUTO,0.000000,0.000000


STARTUPGROUP,Longitudinal
FIELDGROUP,Longitudinal,1,2,3,4,5,6,7,8,9,15,16,17,18,27,28
FIELDGROUP,Transverse,1,2,3,4,10,11,12,13,14,19,20,21,22,27,28

PLOT_APPEARANCE,ALL,HORZ_GRID_ON,VERT_GRID_ON,MARKERS_AND_LINES

[Data]
Time,Comment,Field (Oe),Temperature (K),Long Moment (EMU),Long Scan Std Dev,Long Algorithm,Long Reg Fit,Long Percent Error (%),Trans Moment (EMU),Trans Scan Std Dev,Trans Algorithm,Trans Reg Fit,Trans Percent Error (%),Long Moment [w/o ABS] (EMU),Long Scan Std Dev [w/o ABS],Long Reg Fit [w/o ABS],Long Percent Error [w/o ABS] (%),Trans Moment [w/o ABS] (EMU),Trans Scan Std Dev [w/o ABS],Trans Reg Fit [w/o ABS],Trans Percent Error [w/o ABS] (%),Points per Scan,Scans per Measurement,Scan Length,Delta Temp (K),Rot Position,Error,EC Comp. Running,Using ABS,
1119503968.060,,5.000000e+000,1.998587e+000,-8.441799e-005,1.497561e-006,3,8.902575e-001,1.773983e+000,,,,,,,,,,,,,,32,2,4.000000e+000,2.568007e-003,0.000000e+000,0,,0,
1119504073.130,,1.450000e+001,2.003568e+000,-2.554876e-004,5.351744e-006,3,9.673869e-001,2.094718e+000,,,,,,,,,,,,,,32,2,4.000000e+000,2.511978e-003,0.000000e+000,0,,0,
1119504167.710,,2.400000e+001,2.002558e+000,-5.052774e-006,8.656254e-006,2,1.382845e-001,1.713169e+002,,,,,,,,,,,,,,32,2,4.000000e+000,3.323078e-003,0.000000e+000,0,,0,
1119504260.260,,3.350000e+001,2.002197e+000,4.159929e-004,9.066326e-006,3,9.801848e-001,2.179443e+000,,,,,,,,,,,,,,32,2,4.000000e+000,2.748013e-003,0.000000e+000,0,,0,
1119504348.690,,4.300000e+001,2.002879e+000,8.496143e-004,9.068446e-006,3,9.869304e-001,1.067360e+000,,,,,,,,,,,,,,32,2,4.000000e+000,3.160954e-003,0.000000e+000,0,,0,
1119504429.760,,5.250000e+001,1.999833e+000,1.252756e-003,2.375329e-005,3,9.896880e-001,1.896083e+000,,,,,,,,,,,,,,32,2,4.000000e+000,2.632976e-003,0.000000e+000,0,,0,
1119504530.000,,6.200000e+001,2.002946e+000,1.747739e-003,4.565936e-006,3,9.897670e-001,2.612482e-001,,,,,,,,,,,,,,32,2,4.000000e+000,1.744986e-003,0.000000e+000,0,,0,
1119504614.750,,7.150000e+001,2.000423e+000,2.152545e-003,1.916463e-005,3,9.902458e-001,8.903245e-001,,,,,,,,,,,,,,32,2,4.000000e+000,2.690077e-003,0.000000e+000,0,,0,
1119504695.000,,8.100000e+001,2.002648e+000,2.541691e-003,1.751514e-005,3,9.905028e-001,6.891138e-001,,,,,,,,,,,,,,32,2,4.000000e+000,2.947807e-003,0.000000e+000,0,,0,
1119504780.080,,9.050000e+001,2.007700e+000,2.988907e-003,1.606141e-005,3,9.905639e-001,5.373673e-001,,,,,,,,,,,,,,32,2,4.000000e+000,1.430988e-003,0.000000e+000,0,,0,
1119504864.770,,1.000000e+002,1.999880e+000,3.375643e-003,1.663648e-005,3,9.906698e-001,4.928389e-001,,,,,,,,,,,,,,32,2,4.000000e+000,1.980901e-003,0.000000e+000,0,,0,
1119504879.220,,1.000000e+002,2.002435e+000,3.397672e-003,5.146855e-006,3,9.904839e-001,1.514818e-001,,,,,,,,,,,,,,32,2,4.000000e+000,2.832890e-003,0.000000e+000,0,,0,
1119504964.680,,9.000000e+001,1.999264e+000,3.220710e-003,2.302436e-006,3,9.901540e-001,7.148848e-002,,,,,,,,,,,,,,32,2,4.000000e+000,1.897097e-003,0.000000e+000,0,,0,
1119505050.200,,8.000000e+001,1.999711e+000,2.850658e-003,1.142410e-006,3,9.897252e-001,4.007531e-002,,,,,,,,,,,,,,32,2,4.000000e+000,2.143025e-003,0.000000e+000,0,,0,
1119505135.770,,7.000000e+001,1.999969e+000,2.471823e-003,1.870431e-006,3,9.894041e-001,7.567009e-002,,,,,,,,,,,,,,32,2,4.000000e+000,1.899958e-003,0.000000e+000,0,,0,
1119505221.730,,6.000000e+001,2.000300e+000,2.069125e-003,1.312644e-006,3,9.887719e-001,6.343956e-002,,,,,,,,,,,,,,32,2,4.000000e+000,2.116919e-003,0.000000e+000,0,,0,
1119505308.620,,5.000000e+001,1.999697e+000,1.677614e-003,2.383767e-006,3,9.881020e-001,1.420926e-001,,,,,,,,,,,,,,32,2,4.000000e+000,2.496004e-003,0.000000e+000,0,,0,
1119505393.870,,4.000000e+001,1.999860e+000,1.271618e-003,2.625370e-006,3,9.869636e-001,2.064591e-001,,,,,,,,,,,,,,32,2,4.000000e+000,2.442002e-003,0.000000e+000,0,,0,
1119505479.060,,3.000000e+001,1.999962e+000,9.280618e-004,2.588162e-006,3,9.845665e-001,2.788782e-001,,,,,,,,,,,,,,32,2,4.000000e+000,2.361894e-003,0.000000e+000,0,,0,
1119505571.330,,2.000000e+001,2.001007e+000,5.744152e-004,2.464726e-006,3,9.791198e-001,4.290845e-001,,,,,,,,,,,,,,32,2,4.000000e+000,2.962112e-003,0.000000e+000,0,,0,
1119505657.240,,1.000000e+001,1.999671e+000,3.355358e-004,2.648378e-006,3,9.649886e-001,7.892982e-001,,,,,,,,,,,,,,32,2,4.000000e+000,2.876043e-003,0.000000e+000,0,,0,
1119505741.770,,0.000000e+000,1.999650e+000,2.685286e-004,2.580033e-006,3,9.533989e-001,9.608038e-001,,,,,,,,,,,,,,32,2,4.000000e+000,2.441883e-003,0.000000e+000,0,,0,
1119505835.360,,-1.000000e+001,2.000925e+000,9.852637e-005,3.429792e-006,3,8.941836e-001,3.481091e+000,,,,,,,,,,,,,,32,2,4.000000e+000,2.797008e-003,0.000000e+000,0,,0,
1119505920.220,,-2.000000e+001,1.999399e+000,-3.480499e-004,3.711372e-006,3,9.741762e-001,1.066333e+000,,,,,,,,,,,,,,32,2,4.000000e+000,2.059937e-003,0.000000e+000,0,,0,
1119506013.370,,-3.000000e+001,2.001081e+000,-8.471926e-004,3.018068e-006,3,9.917572e-001,3.562435e-001,,,,,,,,,,,,,,32,2,4.000000e+000,2.661943e-003,0.000000e+000,0,,0,
1119506098.180,,-4.000000e+001,1.999461e+000,-1.308688e-003,9.314289e-007,3,9.945353e-001,7.117270e-002,,,,,,,,,,,,,,32,2,4.000000e+000,2.793074e-003,0.000000e+000,0,,0,
1119506183.040,,-5.000000e+001,1.999684e+000,-1.781531e-003,8.665622e-007,3,9.940705e-001,4.864144e-002,,,,,,,,,,,,,,32,2,4.000000e+000,2.414942e-003,0.000000e+000,0,,0,
1119506268.010,,-6.000000e+001,1.999555e+000,-2.220950e-003,1.567501e-006,3,9.937997e-001,7.057794e-002,,,,,,,,,,,,,,32,2,4.000000e+000,2.360106e-003,0.000000e+000,0,,0,
1119506353.090,,-7.000000e+001,1.999880e+000,-2.665141e-003,2.541817e-006,3,9.933218e-001,9.537272e-002,,,,,,,,,,,,,,32,2,4.000000e+000,1.628041e-003,0.000000e+000,0,,0,
1119506438.000,,-8.000000e+001,1.999773e+000,-3.090262e-003,3.954889e-006,3,9.928548e-001,1.279791e-001,,,,,,,,,,,,,,32,2,4.000000e+000,3.229976e-003,0.000000e+000,0,,0,
1119506522.700,,-9.000000e+001,1.999806e+000,-3.527752e-003,2.315113e-006,3,9.927367e-001,6.562573e-002,,,,,,,,,,,,,,32,2,4.000000e+000,2.470016e-003,0.000000e+000,0,,0,
1119506608.000,,-1.000000e+002,1.999928e+000,-3.941118e-003,2.179124e-006,3,9.930466e-001,5.529203e-002,,,,,,,,,,,,,,32,2,4.000000e+000,2.143979e-003,0.000000e+000,0,,0,
1119506622.830,,-1.000000e+002,2.002490e+000,-3.943413e-003,5.242014e-007,3,9.925665e-001,1.329309e-002,,,,,,,,,,,,,,32,2,4.000000e+000,2.427101e-003,0.000000e+000,0,,0,
1119506708.570,,-9.000000e+001,1.999663e+000,-3.759460e-003,2.396641e-005,3,9.923824e-001,6.374961e-001,,,,,,,,,,,,,,32,2,4.000000e+000,2.250910e-003,0.000000e+000,0,,0,
1119506794.960,,-8.000000e+001,2.000321e+000,-3.401190e-003,2.454132e-005,3,9.923576e-001,7.215510e-001,,,,,,,,,,,,,,32,2,4.000000e+000,2.064109e-003,0.000000e+000,0,,0,
1119506880.590,,-7.000000e+001,1.999765e+000,-3.011832e-003,2.492459e-005,3,9.921560e-001,8.275558e-001,,,,,,,,,,,,,,32,2,4.000000e+000,2.686977e-003,0.000000e+000,0,,0,
1119506965.670,,-6.000000e+001,2.000083e+000,-2.622811e-003,2.515591e-005,3,9.924598e-001,9.591202e-001,,,,,,,,,,,,,,32,2,4.000000e+000,1.955152e-003,0.000000e+000,0,,0,
1119507051.080,,-5.000000e+001,1.999589e+000,-2.217924e-003,2.598436e-005,3,9.927644e-001,1.171562e+000,,,,,,,,,,,,,,32,2,4.000000e+000,2.224088e-003,0.000000e+000,0,,0,
1119507136.930,,-4.000000e+001,1.999887e+000,-1.821144e-003,2.554453e-005,3,9.928516e-001,1.402664e+000,,,,,,,,,,,,,,32,2,4.000000e+000,2.035856e-003,0.000000e+000,0,,0,
1119507221.900,,-3.000000e+001,1.999962e+000,-1.415140e-003,2.829576e-005,3,9.929489e-001,1.999503e+000,,,,,,,,,,,,,,32,2,4.000000e+000,2.091050e-003,0.000000e+000,0,,0,
1119507307.090,,-2.000000e+001,2.000219e+000,-1.036111e-003,2.682318e-005,3,9.927373e-001,2.588831e+000,,,,,,,,,,,,,,32,2,4.000000e+000,1.956105e-003,0.000000e+000,0,,0,
1119507406.280,,-1.000000e+001,2.001999e+000,-6.434433e-004,5.650970e-006,3,9.887711e-001,8.782390e-001,,,,,,,,,,,,,,32,2,4.000000e+000,1.631975e-003,0.000000e+000,0,,0,
1119507491.640,,0.000000e+000,1.999582e+000,-4.330584e-004,2.508102e-005,3,9.856693e-001,5.791602e+000,,,,,,,,,,,,,,32,2,4.000000e+000,2.143025e-003,0.000000e+000,0,,0,
1119507576.550,,1.000000e+001,2.000029e+000,-3.750264e-004,1.997709e-005,3,9.813979e-001,5.326849e+000,,,,,,,,,,,,,,32,2,4.000000e+000,1.520157e-003,0.000000e+000,0,,0,
1119507669.650,,2.000000e+001,2.001314e+000,-1.935039e-004,8.972586e-006,3,9.615974e-001,4.636903e+000,,,,,,,,,,,,,,32,2,4.000000e+000,4.243016e-003,0.000000e+000,0,,0,
1119507754.620,,3.000000e+001,1.999650e+000,2.331282e-004,2.495787e-005,3,9.742925e-001,1.070564e+001,,,,,,,,,,,,,,32,2,4.000000e+000,2.359033e-003,0.000000e+000,0,,0,
1119507840.090,,4.000000e+001,2.000239e+000,7.248037e-004,2.380922e-005,3,9.881187e-001,3.284920e+000,,,,,,,,,,,,,,32,2,4.000000e+000,2.280831e-003,0.000000e+000,0,,0,
1119507940.100,,5.000000e+001,2.001659e+000,1.188637e-003,5.795932e-006,3,9.891518e-001,4.876118e-001,,,,,,,,,,,,,,32,2,4.000000e+000,1.224041e-003,0.000000e+000,0,,0,
1119508025.400,,6.000000e+001,1.999684e+000,1.615953e-003,2.015047e-005,3,9.904662e-001,1.246971e+000,,,,,,,,,,,,,,32,2,4.000000e+000,2.249956e-003,0.000000e+000,0,,0,
1119508110.650,,7.000000e+001,2.000036e+000,2.066050e-003,1.888969e-005,3,9.906516e-001,9.142899e-001,,,,,,,,,,,,,,32,2,4.000000e+000,1.982093e-003,0.000000e+000,0,,0,
1119508196.390,,8.000000e+001,1.999934e+000,2.513232e-003,1.732614e-005,3,9.908212e-001,6.893969e-001,,,,,,,,,,,,,,32,2,4.000000e+000,2.036095e-003,0.000000e+000,0,,0,
1119508281.190,,9.000000e+001,1.999900e+000,2.942425e-003,1.754280e-005,3,9.908112e-001,5.962023e-001,,,,,,,,,,,,,,32,2,4.000000e+000,2.008915e-003,0.000000e+000,0,,0,
1119508361.600,,1.000000e+002,1.999697e+000,3.379689e-003,1.430095e-005,3,9.908242e-001,4.231440e-001,,,,,,,,,,,,,,32,2,4.000000e+000,1.682043e-003,0.000000e+000,0,,0,