File: gmFile/testfile/Bi2201Gd(041029)nonannealed050624.dc.dat
[Header]
TITLE,MPMS DC Measurement
BYAPP,MPMS Measurement,2.0,Summary
FILEOPENTIME, 1119586180.540000 6/24/2005, 1:09:40 PM

INFO, APPNAME, MPMS MultiVu Application, Revision 1.52,  Build 049

INFO, NAME, Bi2201Gd(041029)nonannealed
INFO, WEIGHT, 13.000
INFO, AREA, 1.000
INFO, LENGTH, 0.500
INFO, SHAPE, 0
INFO, COMMENT,
INFO, SEQUENCE FILE: Bi2201Gd(050621byHarada).seq


INFO, BACKGROUND DATA FILE:, None


STARTUPAXIS,X,4,LINEAR,AUTO,0.000000,0.000000
STARTUPAXIS,Y1,5,LINEAR,AUTO,0.000000,0.000000


STARTUPGROUP,Longitudinal
FIELDGROUP,Longitudinal,1,2,3,4,5,6,7,8,9,15,16,17,18,27,28
FIELDGROUP,Transverse,1,2,3,4,10,11,12,13,14,19,20,21,22,27,28

PLOT_APPEARANCE,ALL,HORZ_GRID_ON,VERT_GRID_ON,MARKERS_AND_LINES

[Data]
Time,Comment,Field (Oe),Temperature (K),Long Moment (EMU),Long Scan Std Dev,Long Algorithm,Long Reg Fit,Long Percent Error (%),Trans Moment (EMU),Trans Scan Std Dev,Trans Algorithm,Trans Reg Fit,Trans Percent Error (%),Long Moment [w/o ABS] (EMU),Long Scan Std Dev [w/o ABS],Long Reg Fit [w/o ABS],Long Percent Error [w/o ABS] (%),Trans Moment [w/o ABS] (EMU),Trans Scan Std Dev [w/o ABS],Trans Reg Fit [w/o ABS],Trans Percent Error [w/o ABS] (%),Points per Scan,Scans per Measurement,Scan Length,Delta Temp (K),Rot Position,Error,EC Comp. Running,Using ABS,
1119586180.480,,5.000000e+000,2.000059e+000,-5.253707e-005,3.420918e-007,3,9.639140e-001,6.511436e-001,,,,,,,,,,,,,,32,4,4.000000e+000,1.546144e-003,0.000000e+000,0,,0,
1119586343.280,,5.000000e+000,2.692533e+000,-4.132187e-005,1.204671e-006,3,9.636226e-001,2.915335e+000,,,,,,,,,,,,,,32,4,4.000000e+000,1.939158e-001,0.000000e+000,0,,0,
1119586458.850,,5.000000e+000,3.264935e+000,-3.488325e-005,7.042118e-007,3,9.647380e-001,2.018768e+000,,,,,,,,,,,,,,32,4,4.000000e+000,1.507642e-001,0.000000e+000,0,,0,
1119586593.630,,5.000000e+000,3.882875e+000,-3.022866e-005,5.818843e-007,3,9.740260e-001,1.924942e+000,,,,,,,,,,,,,,32,4,4.000000e+000,1.766670e-001,0.000000e+000,0,,0,
1119586710.400,,5.000000e+000,4.458047e+000,-2.727634e-005,1.403671e-007,3,9.729578e-001,5.146115e-001,,,,,,,,,,,,,,32,4,4.000000e+000,1.601129e-001,0.000000e+000,0,,0,
1119586838.710,,5.000000e+000,5.061510e+000,-2.432611e-005,4.633814e-007,3,9.751259e-001,1.904873e+000,,,,,,,,,,,,,,32,4,4.000000e+000,1.310539e-001,0.000000e+000,0,,0,
1119586951.200,,5.000000e+000,5.636560e+000,-2.255663e-005,9.569429e-007,3,9.757187e-001,4.242403e+000,,,,,,,,,,,,,,32,4,4.000000e+000,1.319461e-001,0.000000e+000,0,,0,
1119587072.910,,5.000000e+000,6.230814e+000,-2.074329e-005,3.343873e-007,3,9.752691e-001,1.612027e+000,,,,,,,,,,,,,,32,4,4.000000e+000,1.338773e-001,0.000000e+000,0,,0,
1119587193.750,,5.000000e+000,6.820223e+000,-1.864792e-005,5.945149e-007,3,9.742984e-001,3.188103e+000,,,,,,,,,,,,,,32,4,4.000000e+000,1.352973e-001,0.000000e+000,0,,0,
1119587317.390,,5.000000e+000,7.420014e+000,-1.743807e-005,7.620062e-007,3,9.670774e-001,4.369786e+000,,,,,,,,,,,,,,32,4,4.000000e+000,1.367183e-001,0.000000e+000,0,,0,
1119587439.540,,5.000000e+000,8.001598e+000,-1.573394e-005,1.134772e-007,3,9.645945e-001,7.212256e-001,,,,,,,,,,,,,,32,4,4.000000e+000,1.362123e-001,0.000000e+000,0,,0,
1119587563.620,,5.000000e+000,8.598985e+000,-1.495660e-005,6.526169e-007,3,9.696971e-001,4.363403e+000,,,,,,,,,,,,,,32,4,4.000000e+000,1.282330e-001,0.000000e+000,0,,0,
1119587682.810,,5.000000e+000,9.196238e+000,-1.384640e-005,6.793431e-007,3,9.621622e-001,4.906281e+000,,,,,,,,,,,,,,32,4,4.000000e+000,1.424904e-001,0.000000e+000,0,,0,
1119587807.320,,5.000000e+000,9.787416e+000,-1.318051e-005,1.067160e-007,3,9.644488e-001,8.096496e-001,,,,,,,,,,,,,,32,4,4.000000e+000,1.364927e-001,0.000000e+000,0,,0,
1119587930.960,,5.000000e+000,1.037695e+001,-1.236932e-005,4.778702e-007,3,9.589508e-001,3.863351e+000,,,,,,,,,,,,,,32,4,4.000000e+000,1.348400e-001,0.000000e+000,0,,0,
1119588058.060,,5.000000e+000,1.097783e+001,-1.198393e-005,6.553748e-007,3,9.632990e-001,5.468779e+000,,,,,,,,,,,,,,32,4,4.000000e+000,1.412191e-001,0.000000e+000,0,,0,
1119588187.300,,5.000000e+000,1.157274e+001,-1.158274e-005,3.602622e-007,3,9.688267e-001,3.110337e+000,,,,,,,,,,,,,,32,4,4.000000e+000,1.450500e-001,0.000000e+000,0,,0,
1119588315.710,,5.000000e+000,1.216852e+001,-1.138219e-005,6.257950e-007,3,9.453241e-001,5.498018e+000,,,,,,,,,,,,,,32,4,4.000000e+000,1.526804e-001,0.000000e+000,0,,0,
1119588436.330,,5.000000e+000,1.276049e+001,-1.011379e-005,2.680008e-007,3,9.528917e-001,2.649855e+000,,,,,,,,,,,,,,32,4,4.000000e+000,1.343403e-001,0.000000e+000,0,,0,
1119588557.660,,5.000000e+000,1.336441e+001,-1.009990e-005,4.247304e-007,3,9.568132e-001,4.205294e+000,,,,,,,,,,,,,,32,4,4.000000e+000,1.439295e-001,0.000000e+000,0,,0,
1119588677.010,,5.000000e+000,1.394760e+001,-9.560334e-006,5.663516e-007,3,9.514152e-001,5.923973e+000,,,,,,,,,,,,,,32,4,4.000000e+000,1.363697e-001,0.000000e+000,0,,0,
1119588802.300,,5.000000e+000,1.455254e+001,-8.726467e-006,1.388520e-006,3,9.372109e-001,1.591160e+001,,,,,,,,,,,,,,32,4,4.000000e+000,1.487303e-001,0.000000e+000,0,,0,
1119588926.810,,5.000000e+000,1.514212e+001,-8.943955e-006,9.544793e-007,3,9.620371e-001,1.067178e+001,,,,,,,,,,,,,,32,4,4.000000e+000,1.533804e-001,0.000000e+000,0,,0,
1119589046.170,,5.000000e+000,1.573095e+001,-8.524734e-006,1.169633e-006,3,9.460400e-001,1.372047e+001,,,,,,,,,,,,,,32,4,4.000000e+000,1.475096e-001,0.000000e+000,0,,0,
1119589172.050,,5.000000e+000,1.632838e+001,-8.333921e-006,8.720950e-007,3,9.443726e-001,1.046440e+001,,,,,,,,,,,,,,32,4,4.000000e+000,1.474895e-001,0.000000e+000,0,,0,
1119589292.340,,5.000000e+000,1.690912e+001,-7.805045e-006,8.723952e-007,3,9.521111e-001,1.117732e+001,,,,,,,,,,,,,,32,4,4.000000e+000,1.296005e-001,0.000000e+000,0,,0,
1119589416.420,,5.000000e+000,1.750288e+001,-7.454478e-006,1.116834e-006,3,9.022876e-001,1.498206e+001,,,,,,,,,,,,,,32,4,4.000000e+000,1.264305e-001,0.000000e+000,0,,0,
1119589543.080,,5.000000e+000,1.810701e+001,-7.496941e-006,6.333186e-007,3,9.590675e-001,8.447694e+000,,,,,,,,,,,,,,32,4,4.000000e+000,1.414108e-001,0.000000e+000,0,,0,
1119589660.730,,5.000000e+000,1.869475e+001,-7.013859e-006,3.317518e-007,3,9.537473e-001,4.729947e+000,,,,,,,,,,,,,,32,4,4.000000e+000,1.413898e-001,0.000000e+000,0,,0,
1119589779.200,,5.000000e+000,1.928676e+001,-6.839113e-006,5.492612e-007,3,9.380555e-001,8.031177e+000,,,,,,,,,,,,,,32,4,4.000000e+000,1.294613e-001,0.000000e+000,0,,0,
1119589902.950,,5.000000e+000,1.988379e+001,-6.784711e-006,6.586131e-007,3,9.422814e-001,9.707312e+000,,,,,,,,,,,,,,32,4,4.000000e+000,1.314793e-001,0.000000e+000,0,,0,
1119590026.530,,5.000000e+000,2.048018e+001,-6.574372e-006,3.209402e-007,3,9.546788e-001,4.881686e+000,,,,,,,,,,,,,,32,4,4.000000e+000,1.378117e-001,0.000000e+000,0,,0,
1119590147.640,,5.000000e+000,2.106763e+001,-6.647545e-006,5.860725e-007,3,9.406111e-001,8.816375e+000,,,,,,,,,,,,,,32,4,4.000000e+000,1.327400e-001,0.000000e+000,0,,0,
1119590269.850,,5.000000e+000,2.166981e+001,-6.516305e-006,7.339744e-007,3,9.365209e-001,1.126366e+001,,,,,,,,,,,,,,32,4,4.000000e+000,1.436405e-001,0.000000e+000,0,,0,
1119590392.770,,5.000000e+000,2.225620e+001,-5.810708e-006,3.115784e-007,3,9.329735e-001,5.362142e+000,,,,,,,,,,,,,,32,4,4.000000e+000,1.374016e-001,0.000000e+000,0,,0,
1119590515.860,,5.000000e+000,2.285500e+001,-5.726023e-006,2.771249e-007,3,9.520376e-001,4.839745e+000,,,,,,,,,,,,,,32,4,4.000000e+000,1.334801e-001,0.000000e+000,0,,0,
1119590640.930,,5.000000e+000,2.344714e+001,-5.403961e-006,5.790580e-007,3,9.172952e-001,1.071544e+001,,,,,,,,,,,,,,32,4,4.000000e+000,1.374111e-001,0.000000e+000,0,,0,
1119590765.000,,5.000000e+000,2.405280e+001,-4.887432e-006,3.176470e-007,3,9.308001e-001,6.499263e+000,,,,,,,,,,,,,,32,4,4.000000e+000,1.392498e-001,0.000000e+000,0,,0,
1119590885.460,,5.000000e+000,2.463851e+001,-5.500901e-006,2.094266e-007,3,9.264693e-001,3.807132e+000,,,,,,,,,,,,,,32,4,4.000000e+000,1.453590e-001,0.000000e+000,0,,0,
1119591006.460,,5.000000e+000,2.521910e+001,-5.325051e-006,8.057546e-008,3,9.359112e-001,1.513140e+000,,,,,,,,,,,,,,32,4,4.000000e+000,1.224499e-001,0.000000e+000,0,,0,
1119591136.360,,5.000000e+000,2.582708e+001,-4.733373e-006,8.234484e-007,3,8.774239e-001,1.739665e+001,,,,,,,,,,,,,,32,4,4.000000e+000,1.359100e-001,0.000000e+000,0,,0,
1119591260.540,,5.000000e+000,2.641628e+001,-4.978824e-006,6.445348e-007,3,9.310282e-001,1.294552e+001,,,,,,,,,,,,,,32,4,4.000000e+000,1.428699e-001,0.000000e+000,0,,0,
1119591382.370,,5.000000e+000,2.701051e+001,-4.594211e-006,3.572760e-007,3,9.209257e-001,7.776656e+000,,,,,,,,,,,,,,32,4,4.000000e+000,1.475601e-001,0.000000e+000,0,,0,
1119591505.950,,5.000000e+000,2.760537e+001,-5.173694e-006,2.826797e-007,3,9.194717e-001,5.463788e+000,,,,,,,,,,,,,,32,4,4.000000e+000,1.391602e-001,0.000000e+000,0,,0,
1119591625.410,,5.000000e+000,2.819145e+001,-4.484103e-006,1.128534e-006,3,8.666441e-001,2.516744e+001,,,,,,,,,,,,,,32,4,4.000000e+000,1.268997e-001,0.000000e+000,0,,0,
1119591756.680,,5.000000e+000,2.879269e+001,-4.198882e-006,2.748738e-007,3,9.166399e-001,6.546357e+000,,,,,,,,,,,,,,32,4,4.000000e+000,1.397095e-001,0.000000e+000,0,,0,
1119591880.210,,5.000000e+000,2.937893e+001,-5.038694e-006,2.657395e-007,3,9.090940e-001,5.273974e+000,,,,,,,,,,,,,,32,4,4.000000e+000,1.364994e-001,0.000000e+000,0,,0,
1119592007.690,,5.000000e+000,2.998461e+001,-4.006500e-006,6.028826e-007,3,9.047523e-001,1.504761e+001,,,,,,,,,,,,,,32,4,4.000000e+000,1.417904e-001,0.000000e+000,0,,0,
1119592131.280,,5.000000e+000,3.057845e+001,-4.125382e-006,4.368826e-007,3,9.294200e-001,1.059011e+001,,,,,,,,,,,,,,32,4,4.000000e+000,1.295795e-001,0.000000e+000,0,,0,
1119592251.290,,5.000000e+000,3.116829e+001,-3.822461e-006,3.576575e-007,3,9.175244e-001,9.356734e+000,,,,,,,,,,,,,,32,4,4.000000e+000,1.410999e-001,0.000000e+000,0,,0,
1119592372.840,,5.000000e+000,3.176166e+001,-3.854064e-006,4.145400e-007,3,8.983419e-001,1.075592e+001,,,,,,,,,,,,,,32,4,4.000000e+000,1.441708e-001,0.000000e+000,0,,0,
1119592498.120,,5.000000e+000,3.235371e+001,-3.831476e-006,5.025462e-007,3,8.674205e-001,1.311626e+001,,,,,,,,,,,,,,32,4,4.000000e+000,1.341820e-001,0.000000e+000,0,,0,
1119592625.820,,5.000000e+000,3.294598e+001,-4.225034e-006,8.094420e-007,3,9.073275e-001,1.915824e+001,,,,,,,,,,,,,,32,4,4.000000e+000,1.329002e-001,0.000000e+000,0,,0,
1119592747.590,,5.000000e+000,3.354110e+001,-3.725117e-006,7.294221e-007,3,8.672901e-001,1.958118e+001,,,,,,,,,,,,,,32,4,4.000000e+000,1.401978e-001,0.000000e+000,0,,0,
1119592871.510,,5.000000e+000,3.413922e+001,-3.843511e-006,2.460444e-007,3,9.144660e-001,6.401553e+000,,,,,,,,,,,,,,32,4,4.000000e+000,1.371613e-001,0.000000e+000,0,,0,
1119592990.860,,5.000000e+000,3.472583e+001,-3.259582e-006,1.395456e-006,3,7.375405e-001,4.281089e+001,,,,,,,,,,,,,,32,4,4.000000e+000,1.322594e-001,0.000000e+000,0,,0,
1119593111.200,,5.000000e+000,3.532496e+001,-3.833927e-006,5.007795e-007,3,8.902386e-001,1.306179e+001,,,,,,,,,,,,,,32,4,4.000000e+000,1.450081e-001,0.000000e+000,0,,0,
1119593236.100,,5.000000e+000,3.591996e+001,-3.305039e-006,4.058760e-007,3,8.958120e-001,1.228052e+001,,,,,,,,,,,,,,32,4,4.000000e+000,1.453781e-001,0.000000e+000,0,,0,
1119593355.950,,5.000000e+000,3.651320e+001,-3.424103e-006,7.067068e-007,3,8.727876e-001,2.063918e+001,,,,,,,,,,,,,,32,4,4.000000e+000,1.321716e-001,0.000000e+000,0,,0,
1119593476.620,,5.000000e+000,3.710129e+001,-3.687124e-006,6.353428e-007,3,8.790331e-001,1.723139e+001,,,,,,,,,,,,,,32,4,4.000000e+000,1.424103e-001,0.000000e+000,0,,0,
1119593598.560,,5.000000e+000,3.769056e+001,-3.541613e-006,1.521487e-007,3,9.041426e-001,4.296027e+000,,,,,,,,,,,,,,32,4,4.000000e+000,1.262512e-001,0.000000e+000,0,,0,
1119593728.340,,5.000000e+000,3.829305e+001,-3.052712e-006,6.146303e-007,3,8.711252e-001,2.013391e+001,,,,,,,,,,,,,,32,4,4.000000e+000,1.464615e-001,0.000000e+000,0,,0,
1119593855.550,,5.000000e+000,3.888644e+001,-2.732755e-006,1.360692e-006,3,6.731543e-001,4.979195e+001,,,,,,,,,,,,,,32,4,4.000000e+000,1.307983e-001,0.000000e+000,0,,0,
1119593978.260,,5.000000e+000,3.948600e+001,-3.267061e-006,6.799547e-007,3,9.016017e-001,2.081243e+001,,,,,,,,,,,,,,32,4,4.000000e+000,1.520691e-001,0.000000e+000,0,,0,
1119594315.000,,5.000000e+000,4.000303e+001,-3.146721e-006,4.784163e-007,3,8.557081e-001,1.520364e+001,,,,,,,,,,,,,,32,4,4.000000e+000,1.417923e-002,0.000000e+000,0,,0,
1119594515.260,,5.000000e+000,4.000060e+001,-3.348619e-006,3.194806e-007,3,9.097769e-001,9.540665e+000,,,,,,,,,,,,,,32,4,4.000000e+000,1.239777e-002,0.000000e+000,0,,0,
1119594587.100,,5.000000e+000,3.914677e+001,-3.044687e-006,9.307236e-007,3,7.955322e-001,3.056878e+001,,,,,,,,,,,,,,32,4,4.000000e+000,4.286995e-001,0.000000e+000,0,,0,
1119594633.960,,5.000000e+000,3.867640e+001,-3.570492e-006,4.000652e-007,3,9.140008e-001,1.120476e+001,,,,,,,,,,,,,,32,4,4.000000e+000,2.621994e-001,0.000000e+000,0,,0,
1119594706.680,,5.000000e+000,3.811745e+001,-3.726704e-006,6.430039e-007,3,9.191977e-001,1.725396e+001,,,,,,,,,,,,,,32,4,4.000000e+000,1.922112e-001,0.000000e+000,0,,0,
1119594803.350,,5.000000e+000,3.753090e+001,-3.292205e-006,4.443884e-007,3,9.066706e-001,1.349820e+001,,,,,,,,,,,,,,32,4,4.000000e+000,1.768875e-001,0.000000e+000,0,,0,
1119594910.620,,5.000000e+000,3.694765e+001,-3.090611e-006,4.681966e-007,3,8.804715e-001,1.514900e+001,,,,,,,,,,,,,,32,4,4.000000e+000,1.519089e-001,0.000000e+000,0,,0,
1119595027.660,,5.000000e+000,3.636269e+001,-3.441006e-006,3.653542e-007,3,9.177294e-001,1.061766e+001,,,,,,,,,,,,,,32,4,4.000000e+000,1.429176e-001,0.000000e+000,0,,0,
1119595147.400,,5.000000e+000,3.577069e+001,-3.073101e-006,8.063407e-007,3,8.304193e-001,2.623866e+001,,,,,,,,,,,,,,32,4,4.000000e+000,1.470604e-001,0.000000e+000,0,,0,
1119595268.620,,5.000000e+000,3.517222e+001,-3.237494e-006,7.724954e-007,3,8.067850e-001,2.386090e+001,,,,,,,,,,,,,,32,4,4.000000e+000,1.506805e-001,0.000000e+000,0,,0,
1119595391.820,,5.000000e+000,3.457597e+001,-3.375030e-006,2.890980e-007,3,8.781432e-001,8.565791e+000,,,,,,,,,,,,,,32,4,4.000000e+000,1.499176e-001,0.000000e+000,0,,0,
1119595508.920,,5.000000e+000,3.399622e+001,-4.053434e-006,4.217134e-007,3,9.265714e-001,1.040386e+001,,,,,,,,,,,,,,32,4,4.000000e+000,1.283417e-001,0.000000e+000,0,,0,
1119595631.460,,5.000000e+000,3.338535e+001,-4.274603e-006,8.195128e-007,3,9.091078e-001,1.917167e+001,,,,,,,,,,,,,,32,4,4.000000e+000,1.439285e-001,0.000000e+000,0,,0,
1119595753.230,,5.000000e+000,3.279514e+001,-4.053533e-006,5.169596e-007,3,9.058747e-001,1.275331e+001,,,,,,,,,,,,,,32,4,4.000000e+000,1.474380e-001,0.000000e+000,0,,0,
1119595876.260,,5.000000e+000,3.220652e+001,-4.804782e-006,4.352881e-007,3,9.172665e-001,9.059475e+000,,,,,,,,,,,,,,32,4,4.000000e+000,1.353226e-001,0.000000e+000,0,,0,
1119595999.790,,5.000000e+000,3.160717e+001,-4.366024e-006,5.213853e-007,3,9.348331e-001,1.194188e+001,,,,,,,,,,,,,,32,4,4.000000e+000,1.427898e-001,0.000000e+000,0,,0,
1119596119.640,,5.000000e+000,3.102048e+001,-4.206224e-006,4.020150e-007,3,9.357314e-001,9.557622e+000,,,,,,,,,,,,,,32,4,4.000000e+000,1.441307e-001,0.000000e+000,0,,0,
1119596240.140,,5.000000e+000,3.042614e+001,-4.535853e-006,5.235097e-007,3,9.163173e-001,1.154159e+001,,,,,,,,,,,,,,32,4,4.000000e+000,1.346207e-001,0.000000e+000,0,,0,
1119596363.560,,5.000000e+000,2.983316e+001,-4.176863e-006,3.772660e-007,3,9.239106e-001,9.032281e+000,,,,,,,,,,,,,,32,4,4.000000e+000,1.405792e-001,0.000000e+000,0,,0,
1119596489.010,,5.000000e+000,2.924476e+001,-4.284066e-006,7.125397e-007,3,9.200555e-001,1.663232e+001,,,,,,,,,,,,,,32,4,4.000000e+000,1.313915e-001,0.000000e+000,0,,0,
1119596613.960,,5.000000e+000,2.864809e+001,-4.609702e-006,1.003025e-006,3,8.767164e-001,2.175899e+001,,,,,,,,,,,,,,32,4,4.000000e+000,1.401806e-001,0.000000e+000,0,,0,
1119596738.920,,5.000000e+000,2.805206e+001,-4.489008e-006,1.117763e-006,3,8.756720e-001,2.489999e+001,,,,,,,,,,,,,,32,4,4.000000e+000,1.373005e-001,0.000000e+000,0,,0,
1119596858.110,,5.000000e+000,2.746400e+001,-4.544921e-006,6.837332e-007,3,9.007884e-001,1.504390e+001,,,,,,,,,,,,,,32,4,4.000000e+000,1.377392e-001,0.000000e+000,0,,0,
1119596982.570,,5.000000e+000,2.686919e+001,-4.484571e-006,6.468641e-007,3,9.008942e-001,1.442421e+001,,,,,,,,,,,,,,32,4,4.000000e+000,1.402702e-001,0.000000e+000,0,,0,
1119597105.050,,5.000000e+000,2.626966e+001,-4.915049e-006,8.086785e-007,3,8.992536e-001,1.645311e+001,,,,,,,,,,,,,,32,4,4.000000e+000,1.483707e-001,0.000000e+000,0,,0,
1119597226.820,,5.000000e+000,2.567873e+001,-4.832839e-006,4.863471e-007,3,9.411438e-001,1.006338e+001,,,,,,,,,,,,,,32,4,4.000000e+000,1.396294e-001,0.000000e+000,0,,0,
1119597352.110,,5.000000e+000,2.508076e+001,-5.008826e-006,4.048151e-007,3,9.359717e-001,8.082036e+000,,,,,,,,,,,,,,32,4,4.000000e+000,1.354389e-001,0.000000e+000,0,,0,
1119597411.870,,5.000000e+000,2.436731e+001,-5.024369e-006,2.138249e-007,3,9.318364e-001,4.255756e+000,,,,,,,,,,,,,,32,4,4.000000e+000,3.129692e-001,0.000000e+000,0,,0,
1119597473.710,,5.000000e+000,2.387453e+001,-5.459051e-006,4.425968e-007,3,9.379143e-001,8.107577e+000,,,,,,,,,,,,,,32,4,4.000000e+000,1.666412e-001,0.000000e+000,0,,0,
1119597582.250,,5.000000e+000,2.328939e+001,-5.021433e-006,7.904908e-007,3,9.180491e-001,1.574233e+001,,,,,,,,,,,,,,32,4,4.000000e+000,1.665592e-001,0.000000e+000,0,,0,
1119597700.890,,5.000000e+000,2.271586e+001,-5.693121e-006,8.547886e-007,3,9.054656e-001,1.501441e+001,,,,,,,,,,,,,,32,4,4.000000e+000,1.278210e-001,0.000000e+000,0,,0,
1119597829.850,,5.000000e+000,2.211831e+001,-5.591072e-006,5.171358e-007,3,9.464498e-001,9.249313e+000,,,,,,,,,,,,,,32,4,4.000000e+000,1.362591e-001,0.000000e+000,0,,0,
1119597956.780,,5.000000e+000,2.151382e+001,-6.025753e-006,6.447460e-007,3,9.383633e-001,1.069984e+001,,,,,,,,,,,,,,32,4,4.000000e+000,1.411304e-001,0.000000e+000,0,,0,
1119598081.960,,5.000000e+000,2.091764e+001,-5.972519e-006,5.091736e-007,3,9.416267e-001,8.525273e+000,,,,,,,,,,,,,,32,4,4.000000e+000,1.420689e-001,0.000000e+000,0,,0,
1119598205.270,,5.000000e+000,2.034337e+001,-6.409218e-006,9.189954e-007,3,9.269916e-001,1.433865e+001,,,,,,,,,,,,,,32,4,4.000000e+000,1.226902e-001,0.000000e+000,0,,0,
1119598340.930,,5.000000e+000,1.974355e+001,-5.935124e-006,1.690046e-007,3,9.411060e-001,2.847533e+000,,,,,,,,,,,,,,32,4,4.000000e+000,1.301098e-001,0.000000e+000,0,,0,
1119598470.940,,5.000000e+000,1.914917e+001,-6.416164e-006,1.022336e-006,3,9.128736e-001,1.593375e+001,,,,,,,,,,,,,,32,4,4.000000e+000,1.313705e-001,0.000000e+000,0,,0,
1119598599.800,,5.000000e+000,1.855324e+001,-6.619908e-006,5.803766e-007,3,9.393036e-001,8.767141e+000,,,,,,,,,,,,,,32,4,4.000000e+000,1.381493e-001,0.000000e+000,0,,0,
1119598726.780,,5.000000e+000,1.795575e+001,-6.939455e-006,2.939515e-007,3,9.405194e-001,4.235945e+000,,,,,,,,,,,,,,32,4,4.000000e+000,1.404209e-001,0.000000e+000,0,,0,
1119598847.290,,5.000000e+000,1.737272e+001,-7.023703e-006,1.049769e-006,3,9.353309e-001,1.494609e+001,,,,,,,,,,,,,,32,4,4.000000e+000,1.293011e-001,0.000000e+000,0,,0,
1119598975.100,,5.000000e+000,1.676549e+001,-6.866357e-006,6.771444e-007,3,9.492999e-001,9.861772e+000,,,,,,,,,,,,,,32,4,4.000000e+000,1.441994e-001,0.000000e+000,0,,0,
1119599103.240,,5.000000e+000,1.618088e+001,-7.966570e-006,6.304179e-007,3,9.407000e-001,7.913292e+000,,,,,,,,,,,,,,32,4,4.000000e+000,1.266193e-001,0.000000e+000,0,,0,
1119599229.900,,5.000000e+000,1.558390e+001,-7.938995e-006,6.683217e-007,3,9.342484e-001,8.418216e+000,,,,,,,,,,,,,,32,4,4.000000e+000,1.365395e-001,0.000000e+000,0,,0,
1119599356.940,,5.000000e+000,1.499768e+001,-8.091220e-006,4.760664e-007,3,9.600496e-001,5.883741e+000,,,,,,,,,,,,,,32,4,4.000000e+000,1.331196e-001,0.000000e+000,0,,0,
1119599478.600,,5.000000e+000,1.440093e+001,-8.336475e-006,3.923779e-007,3,9.546750e-001,4.706761e+000,,,,,,,,,,,,,,32,4,4.000000e+000,1.359396e-001,0.000000e+000,0,,0,
1119599606.420,,5.000000e+000,1.380966e+001,-8.554503e-006,7.496990e-007,3,9.569286e-001,8.763794e+000,,,,,,,,,,,,,,32,4,4.000000e+000,1.254606e-001,0.000000e+000,0,,0,
1119599733.620,,5.000000e+000,1.320996e+001,-9.263250e-006,6.526877e-007,3,9.535365e-001,7.045991e+000,,,,,,,,,,,,,,32,4,4.000000e+000,1.399002e-001,0.000000e+000,0,,0,
1119599864.240,,5.000000e+000,1.261284e+001,-9.053761e-006,6.046108e-007,3,9.341991e-001,6.678007e+000,,,,,,,,,,,,,,32,4,4.000000e+000,1.355095e-001,0.000000e+000,0,,0,
1119599994.850,,5.000000e+000,1.202157e+001,-1.025199e-005,2.812048e-007,3,9.608570e-001,2.742928e+000,,,,,,,,,,,,,,32,4,4.000000e+000,1.398096e-001,0.000000e+000,0,,0,
1119600116.890,,5.000000e+000,1.142974e+001,-1.029239e-005,5.255501e-007,3,9.546214e-001,5.106204e+000,,,,,,,,,,,,,,32,4,4.000000e+000,1.210699e-001,0.000000e+000,0,,0,
1119600245.690,,5.000000e+000,1.083141e+001,-1.075900e-005,7.144653e-007,3,9.485109e-001,6.640628e+000,,,,,,,,,,,,,,32,4,4.000000e+000,1.377602e-001,0.000000e+000,0,,0,
1119600369.280,,5.000000e+000,1.023343e+001,-1.154063e-005,6.839125e-007,3,9.675965e-001,5.926130e+000,,,,,,,,,,,,,,32,4,4.000000e+000,1.448298e-001,0.000000e+000,0,,0,
1119600491.320,,5.000000e+000,9.644882e+000,-1.137868e-005,9.730096e-007,3,9.433537e-001,8.551167e+000,,,,,,,,,,,,,,32,4,4.000000e+000,1.332941e-001,0.000000e+000,0,,0,
1119600612.820,,5.000000e+000,9.055748e+000,-1.246014e-005,7.033963e-007,3,9.597718e-001,5.645170e+000,,,,,,,,,,,,,,32,4,4.000000e+000,1.323595e-001,0.000000e+000,0,,0,
1119600739.420,,5.000000e+000,8.455168e+000,-1.452965e-005,1.126516e-006,3,9.602772e-001,7.753224e+000,,,,,,,,,,,,,,32,4,4.000000e+000,1.470366e-001,0.000000e+000,0,,0,
1119600863.440,,5.000000e+000,7.862009e+000,-1.494123e-005,3.829159e-007,3,9.704871e-001,2.562814e+000,,,,,,,,,,,,,,32,4,4.000000e+000,1.366763e-001,0.000000e+000,0,,0,
1119600991.580,,5.000000e+000,7.279400e+000,-1.559045e-005,5.077269e-007,3,9.692224e-001,3.256654e+000,,,,,,,,,,,,,,32,4,4.000000e+000,1.178341e-001,0.000000e+000,0,,0,
1119601123.730,,5.000000e+000,6.681756e+000,-1.709201e-005,7.195800e-007,3,9.709079e-001,4.210037e+000,,,,,,,,,,,,,,32,4,4.000000e+000,1.245542e-001,0.000000e+000,0,,0,
1119601246.770,,5.000000e+000,6.078895e+000,-1.891540e-005,8.737650e-007,3,9.654397e-001,4.619331e+000,,,,,,,,,,,,,,32,4,4.000000e+000,1.439948e-001,0.000000e+000,0,,0,
1119601370.240,,5.000000e+000,5.486373e+000,-2.016831e-005,6.715119e-007,3,9.742403e-001,3.329540e+000,,,,,,,,,,,,,,32,4,4.000000e+000,1.382957e-001,0.000000e+000,0,,0,
1119601494.260,,5.000000e+000,4.896597e+000,-2.155271e-005,6.535619e-007,3,9.694924e-001,3.032388e+000,,,,,,,,,,,,,,32,4,4.000000e+000,1.342540e-001,0.000000e+000,0,,0,
1119601620.590,,5.000000e+000,4.309288e+000,-2.563526e-005,2.996343e-007,3,9.641382e-001,1.168837e+000,,,,,,,,,,,,,,32,4,4.000000e+000,1.075974e-001,0.000000e+000,0,,0,
1119601728.900,,5.000000e+000,3.777575e+000,-2.719639e-005,7.467071e-007,3,9.667241e-001,2.745611e+000,,,,,,,,,,,,,,32,4,4.000000e+000,7.131815e-002,0.000000e+000,0,,0,
1119601868.190,,5.000000e+000,3.106297e+000,-3.225410e-005,4.399047e-007,3,9.647981e-001,1.363872e+000,,,,,,,,,,,,,,32,4,4.000000e+000,1.420569e-001,0.000000e+000,0,,0,
1119601993.920,,5.000000e+000,2.518485e+000,-3.804185e-005,2.199575e-007,3,9.569110e-001,5.781986e-001,,,,,,,,,,,,,,32,4,4.000000e+000,1.417651e-001,0.000000e+000,0,,0,
1119602271.510,,5.000000e+000,1.997285e+000,-4.583828e-005,4.894924e-007,3,9.586392e-001,1.067868e+000,,,,,,,,,,,,,,32,4,4.000000e+000,3.805041e-003,0.000000e+000,0,,0,